[2022-06-11 14:42:02,918] [builder.py:185]            [INFO]     |====================================================================================================|
[2022-06-11 14:42:02,919] [builder.py:185]            [INFO]     |                            Network Collections Collection in ..Cartoons                            |
[2022-06-11 14:42:02,919] [builder.py:185]            [INFO]     |====================================================================================================|
[2022-06-11 14:42:02,920] [builder.py:186]            [INFO]     |                                                                                                    |
[2022-06-11 14:42:02,920] [builder.py:191]            [INFO]     |============================ Validating Network Collections Attributes =============================|
[2022-06-11 14:42:02,921] [builder.py:212]            [DEBUG]    |                                                                                                    |
[2022-06-11 14:42:02,922] [builder.py:213]            [DEBUG]    | Validating Method: template                                                                        |
[2022-06-11 14:42:02,922] [meta.py:103]               [DEBUG]    | Value: [ordereddict([('name', 'separator'), ('separator', 'network')])]                            |
[2022-06-11 14:42:02,930] [builder.py:430]            [DEBUG]    |                                                                                                    |
[2022-06-11 14:42:02,931] [builder.py:431]            [DEBUG]    | Validating Method: blank_collection                                                                |
[2022-06-11 14:42:02,931] [builder.py:432]            [DEBUG]    | Value: True                                                                                        |
[2022-06-11 14:42:02,932] [builder.py:600]            [DEBUG]    |                                                                                                    |
[2022-06-11 14:42:02,933] [builder.py:604]            [DEBUG]    | Validating Method: sort_title                                                                      |
[2022-06-11 14:42:02,933] [builder.py:605]            [DEBUG]    | Value: !04_!Network Collections                                                                    |
[2022-06-11 14:42:02,934] [builder.py:600]            [DEBUG]    |                                                                                                    |
[2022-06-11 14:42:02,935] [builder.py:604]            [DEBUG]    | Validating Method: url_poster                                                                      |
[2022-06-11 14:42:02,935] [builder.py:605]            [DEBUG]    | Value: https://raw.githubusercontent.com/meisnate12/Plex-Meta-Manager-Images/master/separators/network.jpg |
[2022-06-11 14:42:03,962] [plex.py:742]               [DEBUG]    |                                                                                                    |
[2022-06-11 14:42:03,963] [plex.py:745]               [DEBUG]    | Looking for: Network Collections                                                                   |
[2022-06-11 14:42:03,964] [builder.py:764]            [INFO]     |                                                                                                    |
[2022-06-11 14:42:03,964] [builder.py:765]            [INFO]     | Validation Successful                                                                              |
[2022-06-11 14:42:03,965] [plex_meta_manager.py:539]  [INFO]     |                                                                                                    |
[2022-06-11 14:42:03,966] [plex_meta_manager.py:541]  [INFO]     |============================== Running Network Collections Collection ==============================|
[2022-06-11 14:42:06,445] [builder.py:2383]           [INFO]     |                                                                                                    |
[2022-06-11 14:42:06,595] [builder.py:2384]           [INFO]     |======================== Updating Details of Network Collections Collection ========================|
[2022-06-11 14:42:06,596] [builder.py:2385]           [INFO]     |                                                                                                    |
[2022-06-11 14:42:06,597] [builder.py:2446]           [INFO]     | Collection Metadata Edits                                                                          |
                                                                 | Sort Title | !04_!Network Collections
[2022-06-11 14:43:08,405] [plex_meta_manager.py:668]  [DEBUG]    | Traceback (most recent call last):
                                                                 |   File "/usr/lib/python3.8/site-packages/urllib3/connectionpool.py", line 449, in _make_request
                                                                 |     six.raise_from(e, None)
                                                                 |   File "<string>", line 3, in raise_from
                                                                 |   File "/usr/lib/python3.8/site-packages/urllib3/connectionpool.py", line 444, in _make_request
                                                                 |     httplib_response = conn.getresponse()
                                                                 |   File "/usr/lib/python3.8/http/client.py", line 1386, in getresponse
                                                                 |     response.begin()
                                                                 |   File "/usr/lib/python3.8/http/client.py", line 312, in begin
                                                                 |     version, status, reason = self._read_status()
                                                                 |   File "/usr/lib/python3.8/http/client.py", line 273, in _read_status
                                                                 |     line = str(self.fp.readline(_MAXLINE + 1), "iso-8859-1")
                                                                 |   File "/usr/lib/python3.8/socket.py", line 669, in readinto
                                                                 |     return self._sock.recv_into(b)
                                                                 | socket.timeout: timed out
                                                                 | 
                                                                 | During handling of the above exception, another exception occurred:
                                                                 | 
                                                                 | Traceback (most recent call last):
                                                                 |   File "/usr/lib/python3.8/site-packages/requests/adapters.py", line 440, in send
                                                                 |     resp = conn.urlopen(
                                                                 |   File "/usr/lib/python3.8/site-packages/urllib3/connectionpool.py", line 785, in urlopen
                                                                 |     retries = retries.increment(
                                                                 |   File "/usr/lib/python3.8/site-packages/urllib3/util/retry.py", line 550, in increment
                                                                 |     raise six.reraise(type(error), error, _stacktrace)
                                                                 |   File "/usr/lib/python3.8/site-packages/urllib3/packages/six.py", line 770, in reraise
                                                                 |     raise value
                                                                 |   File "/usr/lib/python3.8/site-packages/urllib3/connectionpool.py", line 703, in urlopen
                                                                 |     httplib_response = self._make_request(
                                                                 |   File "/usr/lib/python3.8/site-packages/urllib3/connectionpool.py", line 451, in _make_request
                                                                 |     self._raise_timeout(err=e, url=url, timeout_value=read_timeout)
                                                                 |   File "/usr/lib/python3.8/site-packages/urllib3/connectionpool.py", line 340, in _raise_timeout
                                                                 |     raise ReadTimeoutError(
                                                                 | urllib3.exceptions.ReadTimeoutError: HTTPConnectionPool(redacted): Read timed out. (read timeout=60)
                                                                 | 
                                                                 | During handling of the above exception, another exception occurred:
                                                                 | 
                                                                 | Traceback (most recent call last):
                                                                 |   File "plex_meta_manager.py", line 620, in run_collection
                                                                 |     details_list = builder.update_details()
                                                                 |   File "/root/Plex-Meta-Manager/modules/builder.py", line 2449, in update_details
                                                                 |     self.obj.saveEdits()
                                                                 |   File "/usr/lib/python3.8/site-packages/plexapi/base.py", line 594, in saveEdits
                                                                 |     return self.reload()
                                                                 |   File "/usr/lib/python3.8/site-packages/plexapi/base.py", line 348, in reload
                                                                 |     return self._reload(key=key, **kwargs)
                                                                 |   File "/usr/lib/python3.8/site-packages/plexapi/base.py", line 357, in _reload
                                                                 |     data = self._server.query(key)
                                                                 |   File "/usr/lib/python3.8/site-packages/plexapi/server.py", line 696, in query
                                                                 |     response = method(url, headers=headers, timeout=timeout, **kwargs)
                                                                 |   File "/usr/lib/python3.8/site-packages/requests/sessions.py", line 542, in get
                                                                 |     return self.request('GET', url, **kwargs)
                                                                 |   File "/usr/lib/python3.8/site-packages/requests/sessions.py", line 529, in request
                                                                 |     resp = self.send(prep, **send_kwargs)
                                                                 |   File "/usr/lib/python3.8/site-packages/requests/sessions.py", line 645, in send
                                                                 |     r = adapter.send(request, **kwargs)
                                                                 |   File "/usr/lib/python3.8/site-packages/requests/adapters.py", line 532, in send
                                                                 |     raise ReadTimeout(e, request=request)
                                                                 | requests.exceptions.ReadTimeout: HTTPConnectionPool(redacted): Read timed out. (read timeout=60)
                                                                 | 
[2022-06-11 14:43:08,529] [plex_meta_manager.py:669]  [ERROR]    | Unknown Error: HTTPConnectionPool(redacted): Read timed out. (read timeout=60)
[2022-06-11 14:43:08,529] [plex_meta_manager.py:674]  [INFO]     | 
[2022-06-11 14:43:08,530] [plex_meta_manager.py:675]  [INFO]     |====================================================================================================|
[2022-06-11 14:43:08,530] [plex_meta_manager.py:675]  [INFO]     |                              Finished Network Collections Collection                               |
[2022-06-11 14:43:08,530] [plex_meta_manager.py:675]  [INFO]     |                                    Collection Run Time: 0:01:05                                    |
[2022-06-11 14:43:08,531] [plex_meta_manager.py:675]  [INFO]     |====================================================================================================|
